Workbook

Sheet Calculator
A2: Independent refund calculator
A3: Spreadsheet assumptions only. Fees rounded on order totals; no application rules or code used.
A5: Ticket price | B5: 20 | D5: Enter your price and quantities in yellow. | G5: HST | H5: 0.09
A6: Total tickets | B6: 1 | D6: Groups are equal sized; returns fill group 1 first. | G6: Organizer fee rate | H6: 0.067
A7: Ticket groups | B7: 1 | D7: This models a first return, with no discounts or prior refunds. | G7: Organizer fee per ticket | H7: 0.67
A8: Tickets being returned | B8: 1 | D8: Flat rate: one charge. Per group: charge × groups. | G8: Showpass fee rate | H8: 0.07
A9: Shipping charge | B9: 10 | D9: Per item: charge × tickets. | G9: Showpass fee per ticket | H9: 0.67
G10: Processing fee rate | H10: 0.05
A11: =IF(AND(COUNT(B5:B9)=5,B5>=0,B6>=1,B6=INT(B6),B7>=1,B7=INT(B7),B7<=B6,MOD(B6,B7)=0,B8>=1,B8<=B6,B8=INT(B8),B9>=0),"Ready","Check quantities: equal-sized groups; return 1 to total tickets.") -> Ready | G11: Processing fee per ticket | H11: 0.69
G12: VAT on Showpass / processing | H12: 0.2
A13: Fee base | B13: Ticket + shipping + organizer + HST | D13: Processing base also includes Showpass fee + its VAT.
G14: Rates copied from your example; all editable.
A17: Flat rate | D17: ="Purchase total: "&TEXT(Math!M6,"$0.00") -> Purchase total: $41.76
A18: Shipping rule | B18: No fees selected | C18: Showpass only | D18: Processing only | E18: Both
A19: Never | B19: =IF($A$11="Ready",TEXT(Math!I13,"$0.00")&" → "&TEXT(Math!I13+Math!H13,"$0.00"),"Check inputs") -> $21.80 → $23.99 | C19: =IF($A$11="Ready",TEXT(Math!J13,"$0.00")&" → "&TEXT(Math!J13+Math!H13,"$0.00"),"Check inputs") -> $25.53 → $27.72 | D19: =IF($A$11="Ready",TEXT(Math!K13,"$0.00")&" → "&TEXT(Math!K13+Math!H13,"$0.00"),"Check inputs") -> $24.94 → $27.13 | E19: =IF($A$11="Ready",TEXT(Math!L13,"$0.00")&" → "&TEXT(Math!L13+Math!H13,"$0.00"),"Check inputs") -> $28.67 → $30.86
A20: After all items returned | B20: =IF($A$11="Ready",TEXT(Math!I14,"$0.00")&" → "&TEXT(Math!I14+Math!H14,"$0.00"),"Check inputs") -> $32.70 → $34.89 | C20: =IF($A$11="Ready",TEXT(Math!J14,"$0.00")&" → "&TEXT(Math!J14+Math!H14,"$0.00"),"Check inputs") -> $36.43 → $38.62 | D20: =IF($A$11="Ready",TEXT(Math!K14,"$0.00")&" → "&TEXT(Math!K14+Math!H14,"$0.00"),"Check inputs") -> $35.84 → $38.03 | E20: =IF($A$11="Ready",TEXT(Math!L14,"$0.00")&" → "&TEXT(Math!L14+Math!H14,"$0.00"),"Check inputs") -> $39.57 → $41.76
A21: Proportional | B21: =IF($A$11="Ready",TEXT(Math!I15,"$0.00")&" → "&TEXT(Math!I15+Math!H15,"$0.00"),"Check inputs") -> $32.70 → $34.89 | C21: =IF($A$11="Ready",TEXT(Math!J15,"$0.00")&" → "&TEXT(Math!J15+Math!H15,"$0.00"),"Check inputs") -> $36.43 → $38.62 | D21: =IF($A$11="Ready",TEXT(Math!K15,"$0.00")&" → "&TEXT(Math!K15+Math!H15,"$0.00"),"Check inputs") -> $35.84 → $38.03 | E21: =IF($A$11="Ready",TEXT(Math!L15,"$0.00")&" → "&TEXT(Math!L15+Math!H15,"$0.00"),"Check inputs") -> $39.57 → $41.76
A22: Unshipped only: not fulfilled | B22: =IF($A$11="Ready",TEXT(Math!I16,"$0.00")&" → "&TEXT(Math!I16+Math!H16,"$0.00"),"Check inputs") -> $32.70 → $34.89 | C22: =IF($A$11="Ready",TEXT(Math!J16,"$0.00")&" → "&TEXT(Math!J16+Math!H16,"$0.00"),"Check inputs") -> $36.43 → $38.62 | D22: =IF($A$11="Ready",TEXT(Math!K16,"$0.00")&" → "&TEXT(Math!K16+Math!H16,"$0.00"),"Check inputs") -> $35.84 → $38.03 | E22: =IF($A$11="Ready",TEXT(Math!L16,"$0.00")&" → "&TEXT(Math!L16+Math!H16,"$0.00"),"Check inputs") -> $39.57 → $41.76
A23: Unshipped only: fulfilled | B23: =IF($A$11="Ready",TEXT(Math!I17,"$0.00")&" → "&TEXT(Math!I17+Math!H17,"$0.00"),"Check inputs") -> $21.80 → $23.99 | C23: =IF($A$11="Ready",TEXT(Math!J17,"$0.00")&" → "&TEXT(Math!J17+Math!H17,"$0.00"),"Check inputs") -> $25.53 → $27.72 | D23: =IF($A$11="Ready",TEXT(Math!K17,"$0.00")&" → "&TEXT(Math!K17+Math!H17,"$0.00"),"Check inputs") -> $24.94 → $27.13 | E23: =IF($A$11="Ready",TEXT(Math!L17,"$0.00")&" → "&TEXT(Math!L17+Math!H17,"$0.00"),"Check inputs") -> $28.67 → $30.86
A25: Withheld fees incl. fee taxes | B25: =IF($A$11="Ready",ROUND(Math!O13-0,2),"Check inputs") -> 9.06 | C25: =IF($A$11="Ready",ROUND(Math!O13-Math!F13,2),"Check inputs") -> 5.33 | D25: =IF($A$11="Ready",ROUND(Math!O13-Math!G13,2),"Check inputs") -> 5.92 | E25: =IF($A$11="Ready",ROUND(Math!O13-SUM(Math!F13:G13),2),"Check inputs") -> 2.19
A26: Display with missing org HST | B26: =IF($A$11="Ready",ROUND(B25-Math!P13,2),"Check inputs") -> 8.88 | C26: =IF($A$11="Ready",ROUND(C25-Math!P13,2),"Check inputs") -> 5.15 | D26: =IF($A$11="Ready",ROUND(D25-Math!P13,2),"Check inputs") -> 5.74 | E26: =IF($A$11="Ready",ROUND(E25-Math!P13,2),"Check inputs") -> 2.01
A27: Bug offset: missing org HST | B27: =IF($A$11="Ready",Math!P13,"Check inputs") -> 0.18 | C27: =IF($A$11="Ready",Math!P13,"Check inputs") -> 0.18 | D27: =IF($A$11="Ready",Math!P13,"Check inputs") -> 0.18 | E27: =IF($A$11="Ready",Math!P13,"Check inputs") -> 0.18
A32: Per group | D32: ="Purchase total: "&TEXT(Math!M7,"$0.00") -> Purchase total: $41.76
A33: Shipping rule | B33: No fees selected | C33: Showpass only | D33: Processing only | E33: Both
A34: Never | B34: =IF($A$11="Ready",TEXT(Math!I18,"$0.00")&" → "&TEXT(Math!I18+Math!H18,"$0.00"),"Check inputs") -> $21.80 → $23.99 | C34: =IF($A$11="Ready",TEXT(Math!J18,"$0.00")&" → "&TEXT(Math!J18+Math!H18,"$0.00"),"Check inputs") -> $25.53 → $27.72 | D34: =IF($A$11="Ready",TEXT(Math!K18,"$0.00")&" → "&TEXT(Math!K18+Math!H18,"$0.00"),"Check inputs") -> $24.94 → $27.13 | E34: =IF($A$11="Ready",TEXT(Math!L18,"$0.00")&" → "&TEXT(Math!L18+Math!H18,"$0.00"),"Check inputs") -> $28.67 → $30.86
A35: After all items returned | B35: =IF($A$11="Ready",TEXT(Math!I19,"$0.00")&" → "&TEXT(Math!I19+Math!H19,"$0.00"),"Check inputs") -> $32.70 → $34.89 | C35: =IF($A$11="Ready",TEXT(Math!J19,"$0.00")&" → "&TEXT(Math!J19+Math!H19,"$0.00"),"Check inputs") -> $36.43 → $38.62 | D35: =IF($A$11="Ready",TEXT(Math!K19,"$0.00")&" → "&TEXT(Math!K19+Math!H19,"$0.00"),"Check inputs") -> $35.84 → $38.03 | E35: =IF($A$11="Ready",TEXT(Math!L19,"$0.00")&" → "&TEXT(Math!L19+Math!H19,"$0.00"),"Check inputs") -> $39.57 → $41.76
A36: Proportional | B36: =IF($A$11="Ready",TEXT(Math!I20,"$0.00")&" → "&TEXT(Math!I20+Math!H20,"$0.00"),"Check inputs") -> $32.70 → $34.89 | C36: =IF($A$11="Ready",TEXT(Math!J20,"$0.00")&" → "&TEXT(Math!J20+Math!H20,"$0.00"),"Check inputs") -> $36.43 → $38.62 | D36: =IF($A$11="Ready",TEXT(Math!K20,"$0.00")&" → "&TEXT(Math!K20+Math!H20,"$0.00"),"Check inputs") -> $35.84 → $38.03 | E36: =IF($A$11="Ready",TEXT(Math!L20,"$0.00")&" → "&TEXT(Math!L20+Math!H20,"$0.00"),"Check inputs") -> $39.57 → $41.76
A37: Unshipped only: not fulfilled | B37: =IF($A$11="Ready",TEXT(Math!I21,"$0.00")&" → "&TEXT(Math!I21+Math!H21,"$0.00"),"Check inputs") -> $32.70 → $34.89 | C37: =IF($A$11="Ready",TEXT(Math!J21,"$0.00")&" → "&TEXT(Math!J21+Math!H21,"$0.00"),"Check inputs") -> $36.43 → $38.62 | D37: =IF($A$11="Ready",TEXT(Math!K21,"$0.00")&" → "&TEXT(Math!K21+Math!H21,"$0.00"),"Check inputs") -> $35.84 → $38.03 | E37: =IF($A$11="Ready",TEXT(Math!L21,"$0.00")&" → "&TEXT(Math!L21+Math!H21,"$0.00"),"Check inputs") -> $39.57 → $41.76
A38: Unshipped only: fulfilled | B38: =IF($A$11="Ready",TEXT(Math!I22,"$0.00")&" → "&TEXT(Math!I22+Math!H22,"$0.00"),"Check inputs") -> $21.80 → $23.99 | C38: =IF($A$11="Ready",TEXT(Math!J22,"$0.00")&" → "&TEXT(Math!J22+Math!H22,"$0.00"),"Check inputs") -> $25.53 → $27.72 | D38: =IF($A$11="Ready",TEXT(Math!K22,"$0.00")&" → "&TEXT(Math!K22+Math!H22,"$0.00"),"Check inputs") -> $24.94 → $27.13 | E38: =IF($A$11="Ready",TEXT(Math!L22,"$0.00")&" → "&TEXT(Math!L22+Math!H22,"$0.00"),"Check inputs") -> $28.67 → $30.86
A40: Withheld fees incl. fee taxes | B40: =IF($A$11="Ready",ROUND(Math!O18-0,2),"Check inputs") -> 9.06 | C40: =IF($A$11="Ready",ROUND(Math!O18-Math!F18,2),"Check inputs") -> 5.33 | D40: =IF($A$11="Ready",ROUND(Math!O18-Math!G18,2),"Check inputs") -> 5.92 | E40: =IF($A$11="Ready",ROUND(Math!O18-SUM(Math!F18:G18),2),"Check inputs") -> 2.19
A41: Display with missing org HST | B41: =IF($A$11="Ready",ROUND(B40-Math!P18,2),"Check inputs") -> 8.88 | C41: =IF($A$11="Ready",ROUND(C40-Math!P18,2),"Check inputs") -> 5.15 | D41: =IF($A$11="Ready",ROUND(D40-Math!P18,2),"Check inputs") -> 5.74 | E41: =IF($A$11="Ready",ROUND(E40-Math!P18,2),"Check inputs") -> 2.01
A42: Bug offset: missing org HST | B42: =IF($A$11="Ready",Math!P18,"Check inputs") -> 0.18 | C42: =IF($A$11="Ready",Math!P18,"Check inputs") -> 0.18 | D42: =IF($A$11="Ready",Math!P18,"Check inputs") -> 0.18 | E42: =IF($A$11="Ready",Math!P18,"Check inputs") -> 0.18
A47: Per item | D47: ="Purchase total: "&TEXT(Math!M8,"$0.00") -> Purchase total: $41.76
A48: Shipping rule | B48: No fees selected | C48: Showpass only | D48: Processing only | E48: Both
A49: Never | B49: =IF($A$11="Ready",TEXT(Math!I23,"$0.00")&" → "&TEXT(Math!I23+Math!H23,"$0.00"),"Check inputs") -> $21.80 → $23.99 | C49: =IF($A$11="Ready",TEXT(Math!J23,"$0.00")&" → "&TEXT(Math!J23+Math!H23,"$0.00"),"Check inputs") -> $25.53 → $27.72 | D49: =IF($A$11="Ready",TEXT(Math!K23,"$0.00")&" → "&TEXT(Math!K23+Math!H23,"$0.00"),"Check inputs") -> $24.94 → $27.13 | E49: =IF($A$11="Ready",TEXT(Math!L23,"$0.00")&" → "&TEXT(Math!L23+Math!H23,"$0.00"),"Check inputs") -> $28.67 → $30.86
A50: After all items returned | B50: =IF($A$11="Ready",TEXT(Math!I24,"$0.00")&" → "&TEXT(Math!I24+Math!H24,"$0.00"),"Check inputs") -> $32.70 → $34.89 | C50: =IF($A$11="Ready",TEXT(Math!J24,"$0.00")&" → "&TEXT(Math!J24+Math!H24,"$0.00"),"Check inputs") -> $36.43 → $38.62 | D50: =IF($A$11="Ready",TEXT(Math!K24,"$0.00")&" → "&TEXT(Math!K24+Math!H24,"$0.00"),"Check inputs") -> $35.84 → $38.03 | E50: =IF($A$11="Ready",TEXT(Math!L24,"$0.00")&" → "&TEXT(Math!L24+Math!H24,"$0.00"),"Check inputs") -> $39.57 → $41.76
A51: Proportional | B51: =IF($A$11="Ready",TEXT(Math!I25,"$0.00")&" → "&TEXT(Math!I25+Math!H25,"$0.00"),"Check inputs") -> $32.70 → $34.89 | C51: =IF($A$11="Ready",TEXT(Math!J25,"$0.00")&" → "&TEXT(Math!J25+Math!H25,"$0.00"),"Check inputs") -> $36.43 → $38.62 | D51: =IF($A$11="Ready",TEXT(Math!K25,"$0.00")&" → "&TEXT(Math!K25+Math!H25,"$0.00"),"Check inputs") -> $35.84 → $38.03 | E51: =IF($A$11="Ready",TEXT(Math!L25,"$0.00")&" → "&TEXT(Math!L25+Math!H25,"$0.00"),"Check inputs") -> $39.57 → $41.76
A52: Unshipped only: not fulfilled | B52: =IF($A$11="Ready",TEXT(Math!I26,"$0.00")&" → "&TEXT(Math!I26+Math!H26,"$0.00"),"Check inputs") -> $32.70 → $34.89 | C52: =IF($A$11="Ready",TEXT(Math!J26,"$0.00")&" → "&TEXT(Math!J26+Math!H26,"$0.00"),"Check inputs") -> $36.43 → $38.62 | D52: =IF($A$11="Ready",TEXT(Math!K26,"$0.00")&" → "&TEXT(Math!K26+Math!H26,"$0.00"),"Check inputs") -> $35.84 → $38.03 | E52: =IF($A$11="Ready",TEXT(Math!L26,"$0.00")&" → "&TEXT(Math!L26+Math!H26,"$0.00"),"Check inputs") -> $39.57 → $41.76
A53: Unshipped only: fulfilled | B53: =IF($A$11="Ready",TEXT(Math!I27,"$0.00")&" → "&TEXT(Math!I27+Math!H27,"$0.00"),"Check inputs") -> $21.80 → $23.99 | C53: =IF($A$11="Ready",TEXT(Math!J27,"$0.00")&" → "&TEXT(Math!J27+Math!H27,"$0.00"),"Check inputs") -> $25.53 → $27.72 | D53: =IF($A$11="Ready",TEXT(Math!K27,"$0.00")&" → "&TEXT(Math!K27+Math!H27,"$0.00"),"Check inputs") -> $24.94 → $27.13 | E53: =IF($A$11="Ready",TEXT(Math!L27,"$0.00")&" → "&TEXT(Math!L27+Math!H27,"$0.00"),"Check inputs") -> $28.67 → $30.86
A55: Withheld fees incl. fee taxes | B55: =IF($A$11="Ready",ROUND(Math!O23-0,2),"Check inputs") -> 9.06 | C55: =IF($A$11="Ready",ROUND(Math!O23-Math!F23,2),"Check inputs") -> 5.33 | D55: =IF($A$11="Ready",ROUND(Math!O23-Math!G23,2),"Check inputs") -> 5.92 | E55: =IF($A$11="Ready",ROUND(Math!O23-SUM(Math!F23:G23),2),"Check inputs") -> 2.19
...

Sheet Math
A2: Independent arithmetic
A3: Order-total fee rounding. Fixed fee portions apply per ticket; refunds allocate original fees by ticket count.
A5: Method | B5: Ticket subtotal | C5: Shipping | D5: Ticket HST | E5: Shipping HST | F5: Organizer fee | G5: Organizer HST | H5: Fee base | I5: Showpass fee | J5: Showpass VAT | K5: Processing fee | L5: Processing VAT | M5: Purchase total | N5: Selected share | O5: Selected org fee | P5: Selected org HST
A6: Flat rate | B6: =Calculator!$B$5*Calculator!$B$6 -> 20 | C6: =Calculator!$B$9 -> 10 | D6: =ROUND(B6*Calculator!$H$5,2) -> 1.8 | E6: =ROUND(C6*Calculator!$H$5,2) -> 0.9 | F6: =ROUND((Calculator!$B$5*Calculator!$H$6+Calculator!$H$7)*Calculator!$B$6,2) -> 2.01 | G6: =ROUND(F6*Calculator!$H$5,2) -> 0.18 | H6: =IF(Calculator!$B$13="Ticket only",B6,SUM(B6:G6)) -> 34.89 | I6: =ROUND(H6*Calculator!$H$8+Calculator!$H$9*Calculator!$B$6,2) -> 3.11 | J6: =ROUND(I6*Calculator!$H$12,2) -> 0.62 | K6: =ROUND((H6+I6+J6)*Calculator!$H$10+Calculator!$H$11*Calculator!$B$6,2) -> 2.62 | L6: =ROUND(K6*Calculator!$H$12,2) -> 0.52 | M6: =ROUND(SUM(B6:G6,I6:L6),2) -> 41.76 | N6: =Calculator!$B$8/Calculator!$B$6 -> 1 | O6: =ROUND(F6*N6,2) -> 2.01 | P6: =ROUND(G6*N6,2) -> 0.18
A7: Per group | B7: =Calculator!$B$5*Calculator!$B$6 -> 20 | C7: =Calculator!$B$9*Calculator!$B$7 -> 10 | D7: =ROUND(B7*Calculator!$H$5,2) -> 1.8 | E7: =ROUND(C7*Calculator!$H$5,2) -> 0.9 | F7: =ROUND((Calculator!$B$5*Calculator!$H$6+Calculator!$H$7)*Calculator!$B$6,2) -> 2.01 | G7: =ROUND(F7*Calculator!$H$5,2) -> 0.18 | H7: =IF(Calculator!$B$13="Ticket only",B7,SUM(B7:G7)) -> 34.89 | I7: =ROUND(H7*Calculator!$H$8+Calculator!$H$9*Calculator!$B$6,2) -> 3.11 | J7: =ROUND(I7*Calculator!$H$12,2) -> 0.62 | K7: =ROUND((H7+I7+J7)*Calculator!$H$10+Calculator!$H$11*Calculator!$B$6,2) -> 2.62 | L7: =ROUND(K7*Calculator!$H$12,2) -> 0.52 | M7: =ROUND(SUM(B7:G7,I7:L7),2) -> 41.76 | N7: =Calculator!$B$8/Calculator!$B$6 -> 1 | O7: =ROUND(F7*N7,2) -> 2.01 | P7: =ROUND(G7*N7,2) -> 0.18
A8: Per item | B8: =Calculator!$B$5*Calculator!$B$6 -> 20 | C8: =Calculator!$B$9*Calculator!$B$6 -> 10 | D8: =ROUND(B8*Calculator!$H$5,2) -> 1.8 | E8: =ROUND(C8*Calculator!$H$5,2) -> 0.9 | F8: =ROUND((Calculator!$B$5*Calculator!$H$6+Calculator!$H$7)*Calculator!$B$6,2) -> 2.01 | G8: =ROUND(F8*Calculator!$H$5,2) -> 0.18 | H8: =IF(Calculator!$B$13="Ticket only",B8,SUM(B8:G8)) -> 34.89 | I8: =ROUND(H8*Calculator!$H$8+Calculator!$H$9*Calculator!$B$6,2) -> 3.11 | J8: =ROUND(I8*Calculator!$H$12,2) -> 0.62 | K8: =ROUND((H8+I8+J8)*Calculator!$H$10+Calculator!$H$11*Calculator!$B$6,2) -> 2.62 | L8: =ROUND(K8*Calculator!$H$12,2) -> 0.52 | M8: =ROUND(SUM(B8:G8,I8:L8),2) -> 41.76 | N8: =Calculator!$B$8/Calculator!$B$6 -> 1 | O8: =ROUND(F8*N8,2) -> 2.01 | P8: =ROUND(G8*N8,2) -> 0.18
A12: Method | B12: Shipping rule | C12: Returned shipping | D12: Returned shipping HST | E12: Ticket + HST | F12: Showpass + VAT | G12: Processing + VAT | H12: Org fee + HST | I12: No fees credit | J12: Showpass credit | K12: Processing credit | L12: Both credit | M12: Shipping withheld | N12: Shipping HST withheld | O12: Selected fees incl. tax | P12: Organizer HST offset
A13: Flat rate | B13: Never | C13: =ROUND(0,2) -> 0 | D13: =IF(C6=0,0,ROUND(E6*C13/C6,2)) -> 0 | E13: =ROUND(B6*N6,2)+ROUND(D6*N6,2) -> 21.8 | F13: =ROUND(I6*N6,2)+ROUND(J6*N6,2) -> 3.73 | G13: =ROUND(K6*N6,2)+ROUND(L6*N6,2) -> 3.14 | H13: =SUM(O6:P6) -> 2.19 | I13: =ROUND(SUM(C13:E13),2) -> 21.8 | J13: =ROUND(I13+F13,2) -> 25.53 | K13: =ROUND(I13+G13,2) -> 24.94 | L13: =ROUND(SUM(I13,F13,G13),2) -> 28.67 | M13: =ROUND(C6-C13,2) -> 10 | N13: =ROUND(E6-D13,2) -> 0.9 | O13: =ROUND(SUM(F13:H13),2) -> 9.06 | P13: =P6 -> 0.18
A14: Flat rate | B14: After all items returned | C14: =ROUND(IF(Calculator!$B$8=Calculator!$B$6,C6,0),2) -> 10 | D14: =IF(C6=0,0,ROUND(E6*C14/C6,2)) -> 0.9 | E14: =ROUND(B6*N6,2)+ROUND(D6*N6,2) -> 21.8 | F14: =ROUND(I6*N6,2)+ROUND(J6*N6,2) -> 3.73 | G14: =ROUND(K6*N6,2)+ROUND(L6*N6,2) -> 3.14 | H14: =SUM(O6:P6) -> 2.19 | I14: =ROUND(SUM(C14:E14),2) -> 32.7 | J14: =ROUND(I14+F14,2) -> 36.43 | K14: =ROUND(I14+G14,2) -> 35.84 | L14: =ROUND(SUM(I14,F14,G14),2) -> 39.57 | M14: =ROUND(C6-C14,2) -> 0 | N14: =ROUND(E6-D14,2) -> 0 | O14: =ROUND(SUM(F14:H14),2) -> 9.06 | P14: =P6 -> 0.18
A15: Flat rate | B15: Proportional | C15: =ROUND(C6*N6,2) -> 10 | D15: =IF(C6=0,0,ROUND(E6*C15/C6,2)) -> 0.9 | E15: =ROUND(B6*N6,2)+ROUND(D6*N6,2) -> 21.8 | F15: =ROUND(I6*N6,2)+ROUND(J6*N6,2) -> 3.73 | G15: =ROUND(K6*N6,2)+ROUND(L6*N6,2) -> 3.14 | H15: =SUM(O6:P6) -> 2.19 | I15: =ROUND(SUM(C15:E15),2) -> 32.7 | J15: =ROUND(I15+F15,2) -> 36.43 | K15: =ROUND(I15+G15,2) -> 35.84 | L15: =ROUND(SUM(I15,F15,G15),2) -> 39.57 | M15: =ROUND(C6-C15,2) -> 0 | N15: =ROUND(E6-D15,2) -> 0 | O15: =ROUND(SUM(F15:H15),2) -> 9.06 | P15: =P6 -> 0.18
A16: Flat rate | B16: Unshipped only: not fulfilled | C16: =ROUND(C6*N6,2) -> 10 | D16: =IF(C6=0,0,ROUND(E6*C16/C6,2)) -> 0.9 | E16: =ROUND(B6*N6,2)+ROUND(D6*N6,2) -> 21.8 | F16: =ROUND(I6*N6,2)+ROUND(J6*N6,2) -> 3.73 | G16: =ROUND(K6*N6,2)+ROUND(L6*N6,2) -> 3.14 | H16: =SUM(O6:P6) -> 2.19 | I16: =ROUND(SUM(C16:E16),2) -> 32.7 | J16: =ROUND(I16+F16,2) -> 36.43 | K16: =ROUND(I16+G16,2) -> 35.84 | L16: =ROUND(SUM(I16,F16,G16),2) -> 39.57 | M16: =ROUND(C6-C16,2) -> 0 | N16: =ROUND(E6-D16,2) -> 0 | O16: =ROUND(SUM(F16:H16),2) -> 9.06 | P16: =P6 -> 0.18
A17: Flat rate | B17: Unshipped only: fulfilled | C17: =ROUND(0,2) -> 0 | D17: =IF(C6=0,0,ROUND(E6*C17/C6,2)) -> 0 | E17: =ROUND(B6*N6,2)+ROUND(D6*N6,2) -> 21.8 | F17: =ROUND(I6*N6,2)+ROUND(J6*N6,2) -> 3.73 | G17: =ROUND(K6*N6,2)+ROUND(L6*N6,2) -> 3.14 | H17: =SUM(O6:P6) -> 2.19 | I17: =ROUND(SUM(C17:E17),2) -> 21.8 | J17: =ROUND(I17+F17,2) -> 25.53 | K17: =ROUND(I17+G17,2) -> 24.94 | L17: =ROUND(SUM(I17,F17,G17),2) -> 28.67 | M17: =ROUND(C6-C17,2) -> 10 | N17: =ROUND(E6-D17,2) -> 0.9 | O17: =ROUND(SUM(F17:H17),2) -> 9.06 | P17: =P6 -> 0.18
A18: Per group | B18: Never | C18: =ROUND(0,2) -> 0 | D18: =IF(C7=0,0,ROUND(E7*C18/C7,2)) -> 0 | E18: =ROUND(B7*N7,2)+ROUND(D7*N7,2) -> 21.8 | F18: =ROUND(I7*N7,2)+ROUND(J7*N7,2) -> 3.73 | G18: =ROUND(K7*N7,2)+ROUND(L7*N7,2) -> 3.14 | H18: =SUM(O7:P7) -> 2.19 | I18: =ROUND(SUM(C18:E18),2) -> 21.8 | J18: =ROUND(I18+F18,2) -> 25.53 | K18: =ROUND(I18+G18,2) -> 24.94 | L18: =ROUND(SUM(I18,F18,G18),2) -> 28.67 | M18: =ROUND(C7-C18,2) -> 10 | N18: =ROUND(E7-D18,2) -> 0.9 | O18: =ROUND(SUM(F18:H18),2) -> 9.06 | P18: =P7 -> 0.18
A19: Per group | B19: After all items returned | C19: =ROUND(MIN(C7,INT(Calculator!$B$8/(Calculator!$B$6/Calculator!$B$7))*Calculator!$B$9),2) -> 10 | D19: =IF(C7=0,0,ROUND(E7*C19/C7,2)) -> 0.9 | E19: =ROUND(B7*N7,2)+ROUND(D7*N7,2) -> 21.8 | F19: =ROUND(I7*N7,2)+ROUND(J7*N7,2) -> 3.73 | G19: =ROUND(K7*N7,2)+ROUND(L7*N7,2) -> 3.14 | H19: =SUM(O7:P7) -> 2.19 | I19: =ROUND(SUM(C19:E19),2) -> 32.7 | J19: =ROUND(I19+F19,2) -> 36.43 | K19: =ROUND(I19+G19,2) -> 35.84 | L19: =ROUND(SUM(I19,F19,G19),2) -> 39.57 | M19: =ROUND(C7-C19,2) -> 0 | N19: =ROUND(E7-D19,2) -> 0 | O19: =ROUND(SUM(F19:H19),2) -> 9.06 | P19: =P7 -> 0.18
A20: Per group | B20: Proportional | C20: =ROUND(C7*N7,2) -> 10 | D20: =IF(C7=0,0,ROUND(E7*C20/C7,2)) -> 0.9 | E20: =ROUND(B7*N7,2)+ROUND(D7*N7,2) -> 21.8 | F20: =ROUND(I7*N7,2)+ROUND(J7*N7,2) -> 3.73 | G20: =ROUND(K7*N7,2)+ROUND(L7*N7,2) -> 3.14 | H20: =SUM(O7:P7) -> 2.19 | I20: =ROUND(SUM(C20:E20),2) -> 32.7 | J20: =ROUND(I20+F20,2) -> 36.43 | K20: =ROUND(I20+G20,2) -> 35.84 | L20: =ROUND(SUM(I20,F20,G20),2) -> 39.57 | M20: =ROUND(C7-C20,2) -> 0 | N20: =ROUND(E7-D20,2) -> 0 | O20: =ROUND(SUM(F20:H20),2) -> 9.06 | P20: =P7 -> 0.18
A21: Per group | B21: Unshipped only: not fulfilled | C21: =ROUND(C7*N7,2) -> 10 | D21: =IF(C7=0,0,ROUND(E7*C21/C7,2)) -> 0.9 | E21: =ROUND(B7*N7,2)+ROUND(D7*N7,2) -> 21.8 | F21: =ROUND(I7*N7,2)+ROUND(J7*N7,2) -> 3.73 | G21: =ROUND(K7*N7,2)+ROUND(L7*N7,2) -> 3.14 | H21: =SUM(O7:P7) -> 2.19 | I21: =ROUND(SUM(C21:E21),2) -> 32.7 | J21: =ROUND(I21+F21,2) -> 36.43 | K21: =ROUND(I21+G21,2) -> 35.84 | L21: =ROUND(SUM(I21,F21,G21),2) -> 39.57 | M21: =ROUND(C7-C21,2) -> 0 | N21: =ROUND(E7-D21,2) -> 0 | O21: =ROUND(SUM(F21:H21),2) -> 9.06 | P21: =P7 -> 0.18
A22: Per group | B22: Unshipped only: fulfilled | C22: =ROUND(0,2) -> 0 | D22: =IF(C7=0,0,ROUND(E7*C22/C7,2)) -> 0 | E22: =ROUND(B7*N7,2)+ROUND(D7*N7,2) -> 21.8 | F22: =ROUND(I7*N7,2)+ROUND(J7*N7,2) -> 3.73 | G22: =ROUND(K7*N7,2)+ROUND(L7*N7,2) -> 3.14 | H22: =SUM(O7:P7) -> 2.19 | I22: =ROUND(SUM(C22:E22),2) -> 21.8 | J22: =ROUND(I22+F22,2) -> 25.53 | K22: =ROUND(I22+G22,2) -> 24.94 | L22: =ROUND(SUM(I22,F22,G22),2) -> 28.67 | M22: =ROUND(C7-C22,2) -> 10 | N22: =ROUND(E7-D22,2) -> 0.9 | O22: =ROUND(SUM(F22:H22),2) -> 9.06 | P22: =P7 -> 0.18
A23: Per item | B23: Never | C23: =ROUND(0,2) -> 0 | D23: =IF(C8=0,0,ROUND(E8*C23/C8,2)) -> 0 | E23: =ROUND(B8*N8,2)+ROUND(D8*N8,2) -> 21.8 | F23: =ROUND(I8*N8,2)+ROUND(J8*N8,2) -> 3.73 | G23: =ROUND(K8*N8,2)+ROUND(L8*N8,2) -> 3.14 | H23: =SUM(O8:P8) -> 2.19 | I23: =ROUND(SUM(C23:E23),2) -> 21.8 | J23: =ROUND(I23+F23,2) -> 25.53 | K23: =ROUND(I23+G23,2) -> 24.94 | L23: =ROUND(SUM(I23,F23,G23),2) -> 28.67 | M23: =ROUND(C8-C23,2) -> 10 | N23: =ROUND(E8-D23,2) -> 0.9 | O23: =ROUND(SUM(F23:H23),2) -> 9.06 | P23: =P8 -> 0.18
A24: Per item | B24: After all items returned | C24: =ROUND(MIN(C8,INT(Calculator!$B$8/(Calculator!$B$6/Calculator!$B$7))*Calculator!$B$9*(Calculator!$B$6/Calculator!$B$7)),2) -> 10 | D24: =IF(C8=0,0,ROUND(E8*C24/C8,2)) -> 0.9 | E24: =ROUND(B8*N8,2)+ROUND(D8*N8,2) -> 21.8 | F24: =ROUND(I8*N8,2)+ROUND(J8*N8,2) -> 3.73 | G24: =ROUND(K8*N8,2)+ROUND(L8*N8,2) -> 3.14 | H24: =SUM(O8:P8) -> 2.19 | I24: =ROUND(SUM(C24:E24),2) -> 32.7 | J24: =ROUND(I24+F24,2) -> 36.43 | K24: =ROUND(I24+G24,2) -> 35.84 | L24: =ROUND(SUM(I24,F24,G24),2) -> 39.57 | M24: =ROUND(C8-C24,2) -> 0 | N24: =ROUND(E8-D24,2) -> 0 | O24: =ROUND(SUM(F24:H24),2) -> 9.06 | P24: =P8 -> 0.18
A25: Per item | B25: Proportional | C25: =ROUND(C8*N8,2) -> 10 | D25: =IF(C8=0,0,ROUND(E8*C25/C8,2)) -> 0.9 | E25: =ROUND(B8*N8,2)+ROUND(D8*N8,2) -> 21.8 | F25: =ROUND(I8*N8,2)+ROUND(J8*N8,2) -> 3.73 | G25: =ROUND(K8*N8,2)+ROUND(L8*N8,2) -> 3.14 | H25: =SUM(O8:P8) -> 2.19 | I25: =ROUND(SUM(C25:E25),2) -> 32.7 | J25: =ROUND(I25+F25,2) -> 36.43 | K25: =ROUND(I25+G25,2) -> 35.84 | L25: =ROUND(SUM(I25,F25,G25),2) -> 39.57 | M25: =ROUND(C8-C25,2) -> 0 | N25: =ROUND(E8-D25,2) -> 0 | O25: =ROUND(SUM(F25:H25),2) -> 9.06 | P25: =P8 -> 0.18
A26: Per item | B26: Unshipped only: not fulfilled | C26: =ROUND(C8*N8,2) -> 10 | D26: =IF(C8=0,0,ROUND(E8*C26/C8,2)) -> 0.9 | E26: =ROUND(B8*N8,2)+ROUND(D8*N8,2) -> 21.8 | F26: =ROUND(I8*N8,2)+ROUND(J8*N8,2) -> 3.73 | G26: =ROUND(K8*N8,2)+ROUND(L8*N8,2) -> 3.14 | H26: =SUM(O8:P8) -> 2.19 | I26: =ROUND(SUM(C26:E26),2) -> 32.7 | J26: =ROUND(I26+F26,2) -> 36.43 | K26: =ROUND(I26+G26,2) -> 35.84 | L26: =ROUND(SUM(I26,F26,G26),2) -> 39.57 | M26: =ROUND(C8-C26,2) -> 0 | N26: =ROUND(E8-D26,2) -> 0 | O26: =ROUND(SUM(F26:H26),2) -> 9.06 | P26: =P8 -> 0.18
A27: Per item | B27: Unshipped only: fulfilled | C27: =ROUND(0,2) -> 0 | D27: =IF(C8=0,0,ROUND(E8*C27/C8,2)) -> 0 | E27: =ROUND(B8*N8,2)+ROUND(D8*N8,2) -> 21.8 | F27: =ROUND(I8*N8,2)+ROUND(J8*N8,2) -> 3.73 | G27: =ROUND(K8*N8,2)+ROUND(L8*N8,2) -> 3.14 | H27: =SUM(O8:P8) -> 2.19 | I27: =ROUND(SUM(C27:E27),2) -> 21.8 | J27: =ROUND(I27+F27,2) -> 25.53 | K27: =ROUND(I27+G27,2) -> 24.94 | L27: =ROUND(SUM(I27,F27,G27),2) -> 28.67 | M27: =ROUND(C8-C27,2) -> 10 | N27: =ROUND(E8-D27,2) -> 0.9 | O27: =ROUND(SUM(F27:H27),2) -> 9.06 | P27: =P8 -> 0.18
A31: Model assumptions
A33: Shipping | B33: Flat = one charge; group = charge × groups; item = charge × ticket quantity. Equal-sized groups, same ticket price/rates.
A34: Tax | B34: HST calculated separately on ticket subtotal, shipping, and organizer fee; each rounded to cents at order level.
A35: Fee base | B35: Choose ticket only, or ticket + shipping + organizer fee + HST on all three. Processing adds Showpass fee and its VAT.
A36: Fee rounding | B36: Percentage + per-ticket fixed fees rounded once on each original order total. Each fee tax is rounded separately.
A37: Refund allocation | B37: First return only. Allocate each original fee/tax by returned-ticket proportion, rounding each component separately.
A38: After all | B38: Flat: return shipping once all tickets return. Group/item: return charges for fully returned groups; group 1 fills first.
A39: Proportional | B39: Shipping and its tax allocated by number returned / number purchased. Unshipped-only uses same share when unfulfilled.
A40: Organizer fees | B40: Excluded in the first value; second value hypothetically adds the allocated organizer fee and its HST.
A41: Withheld display | B41: True withheld fees = unselected Showpass/processing including VAT + organizer fee/HST. Simulated bug display subtracts organizer HST.
A42: Source inputs | B42: Rates from the user’s del.json example and earlier screenshots. Bug-display offset from the user’s screenshots and discussion.
A43: Scope | B43: Independent arithmetic assumptions; no backend source, app execution, saved invoice values, authorization gates, discounts or prior refunds.
